<?xml version="1.0" ?>
<!-- =================================================================================== -->
<!-- |    This document was autogenerated by xacro from delto_3f_macro.xacro           | -->
<!-- |    EDITING THIS FILE BY HAND IS NOT RECOMMENDED                                 | -->
<!-- =================================================================================== -->
<robot name="delto_3f">
  <!-- <xacro:arg name="parent" default="default_link"/>
  <xacro:arg name="prefix" default="default_prefix"/> -->
  <!--material -->
  <material name="silver">
    <color rgba="0.700 0.700 0.700 1.000"/>
  </material>
  <material name="black">
    <color rgba="0.196 0.196 0.196 1.0"/>
  </material>
  <material name="white">
    <color rgba="1.0 1.0 1.0 1.0"/>
  </material>
  <!--link -->
  <!--Joint -->
  <!-- Tool frame used by the arm -->
  <link name="lefttool_frame"/>
  <joint name="lefttool_frame_joint" type="fixed">
    <origin rpy="0 0 0" xyz="0 0 0.20"/>
    <parent link="ee_link"/>
    <child link="lefttool_frame"/>
    <axis xyz="0 0 0"/>
  </joint>
  <!-- Gripper description -->
  <joint name="leftdelto_3f_base_link" type="fixed">
    <parent link="ee_link"/>
    <child link="leftdelto_base_link"/>
    <origin rpy="0.0 0.0 1.57" xyz="0.0 0.0 0.1"/>
  </joint>
  <link name="leftdelto_base_link">
    <inertial>
      <origin rpy="5.671320207730568e-06 0.0032948722942074404 -0.00044870150924543735" xyz="0.00045499721796859983 -2.051648304165415e-06 -0.05218562175888181"/>
      <mass value="0.370"/>
      <inertia ixx="0.0009935903471030175" ixy="0" ixz="0" iyy="0.000980251548061173" iyz="0" izz="0.0003178199035240808"/>
    </inertial>
    <visual>
      <origin rpy="5.671320207730568e-06 0.0032948722942074404 -0.00044870150924543735" xyz="0.00045499721796859983 -2.051648304165415e-06 -0.05218562175888181"/>
      <geometry>
        <mesh filename="../meshes/delto_base_link.stl"/>
      </geometry>
      <material name="black"/>
    </visual>
    <collision>
      <origin rpy="5.671320207730568e-06 0.0032948722942074404 -0.00044870150924543735" xyz="0.00045499721796859983 -2.051648304165415e-06 -0.05218562175888181"/>
      <geometry>
        <mesh filename="../meshes/delto_base_link.stl"/>
      </geometry>
    </collision>
  </link>
   --&gt;
    
  <joint name="leftF1M1" type="revolute">
    <origin rpy="0 0 0" xyz="0.0265 0.0 0.0"/>
    <parent link="leftdelto_base_link"/>
    <child link="leftF1_01"/>
    <axis xyz="0.0 0.0 1.0"/>
    <limit effort="10.0" lower="-1.0472" upper="1.0472" velocity="5.0"/>
    <dynamics damping="1.1" friction="1.1"/>
  </joint>
  <joint name="leftF1M2" type="revolute">
    <origin rpy="-3.1415926207728213 -1.570796290294655 0.0" xyz="0.0 0.0 0.0"/>
    <parent link="leftF1_01"/>
    <child link="leftF1_02"/>
    <axis xyz="0.0 0.0 1.0"/>
    <limit effort="10.0" lower="-1.76278" upper="1.76278" velocity="5.0"/>
    <dynamics damping="1.1" friction="1.1"/>
  </joint>
  <joint name="leftF1M3" type="revolute">
    <origin rpy="-1.5707963295583207 -1.5707963267948966 0.0" xyz="0.02022 0.0 0.03136"/>
    <parent link="leftF1_02"/>
    <child link="leftF1_03"/>
    <axis xyz="0.0 0.0 1.0"/>
    <limit effort="10.0" lower="-0.15708" upper="2.53073" velocity="5.0"/>
    <dynamics damping="1.1" friction="1.1"/>
  </joint>
  <joint name="leftF1M4" type="revolute">
    <origin rpy="0 0 0" xyz="0.0434 0.0 0.0"/>
    <parent link="leftF1_03"/>
    <child link="leftF1_04"/>
    <axis xyz="0.0 0.0 1.0"/>
    <limit effort="10.0" lower="-0.226893" upper="2.02458" velocity="5.0"/>
    <dynamics damping="1.1" friction="1.1"/>
  </joint>
  <joint name="leftTIP1" type="fixed">
    <origin rpy="0 0 0" xyz="0.0 0.0 0.0"/>
    <parent link="leftF1_04"/>
    <child link="leftF1_TIP"/>
  </joint>
  <joint name="leftF2M1" type="revolute">
    <origin rpy="0 0 -3.14" xyz="-0.01334 0.023 0.0"/>
    <parent link="leftdelto_base_link"/>
    <child link="leftF2_01"/>
    <axis xyz="0.0 0.0 1.0"/>
    <limit effort="10.0" lower="-1.91986" upper="0.139626" velocity="5.0"/>
    <dynamics damping="1.1" friction="1.1"/>
  </joint>
  <joint name="leftF2M2" type="revolute">
    <origin rpy="-3.14 -1.57 0" xyz="0.0 0.0 0.0"/>
    <parent link="leftF2_01"/>
    <child link="leftF2_02"/>
    <axis xyz="0.0 0.0 1.0"/>
    <limit effort="10.0" lower="-1.76278" upper="1.76278" velocity="5.0"/>
    <dynamics damping="1.1" friction="1.1"/>
  </joint>
  <joint name="leftF2M3" type="revolute">
    <origin rpy="-1.57 -1.57 0" xyz="0.02022 0.0 0.03136"/>
    <parent link="leftF2_02"/>
    <child link="leftF2_03"/>
    <axis xyz="0.0 0.0 1.0"/>
    <limit effort="10.0" lower="-0.15708" upper="2.53073" velocity="5.0"/>
    <dynamics damping="1.1" friction="1.1"/>
  </joint>
  <joint name="leftF2M4" type="revolute">
    <origin rpy="0 0 0" xyz="0.0434 0.0 0.0"/>
    <parent link="leftF2_03"/>
    <child link="leftF2_04"/>
    <axis xyz="0.0434 0.0 1.0"/>
    <limit effort="10.0" lower="-0.226893" upper="2.02458" velocity="5.0"/>
    <dynamics damping="1.1" friction="1.1"/>
  </joint>
  <joint name="leftTIP2" type="fixed">
    <origin rpy="0 0 0" xyz="0.0 0.0 0.0"/>
    <parent link="leftF2_04"/>
    <child link="leftF2_TIP"/>
  </joint>
  <joint name="leftF3M1" type="revolute">
    <origin rpy="0 0 -3.14" xyz="-0.01334 -0.023 0.0"/>
    <parent link="leftdelto_base_link"/>
    <child link="leftF3_01"/>
    <axis xyz=".0 0.0 1.0"/>
    <limit effort="10.0" lower="-0.0872665" upper="2.00713" velocity="5.0"/>
    <dynamics damping="1.1" friction="1.1"/>
  </joint>
  <joint name="leftF3M2" type="revolute">
    <origin rpy="-3.14 -1.57 0" xyz="0.0 0.0 0.0"/>
    <parent link="leftF3_01"/>
    <child link="leftF3_02"/>
    <axis xyz="0.0 0.0 1.0"/>
    <limit effort="10.0" lower="-1.76278" upper="1.76278" velocity="5.0"/>
    <dynamics damping="1.1" friction="1.1"/>
  </joint>
  <joint name="leftF3M3" type="revolute">
    <origin rpy="-1.57 -1.57 0" xyz="0.02022 0.0 0.03136"/>
    <parent link="leftF3_02"/>
    <child link="leftF3_03"/>
    <axis xyz="0.0 0.0 1.0"/>
    <limit effort="10.0" lower="-0.15708" upper="2.53073" velocity="5.0"/>
    <dynamics damping="1.1" friction="1.1"/>
  </joint>
  <joint name="leftF3M4" type="revolute">
    <origin rpy="0 0 0" xyz="0.0434 0.0 0.0"/>
    <parent link="leftF3_03"/>
    <child link="leftF3_04"/>
    <axis xyz="0.0 0.0 1.0"/>
    <limit effort="10.0" lower="-0.226893" upper="2.02458" velocity="5.0"/>
    <dynamics damping="1.1" friction="1.1"/>
  </joint>
  <joint name="leftTIP3" type="fixed">
    <origin rpy="0 0 0" xyz="0.0 0.0 0.0"/>
    <parent link="leftF3_04"/>
    <child link="leftF3_TIP"/>
  </joint>
  <link name="leftF1_01">
    <inertial>
      <origin rpy="-0.17662368646091148 -1.9303231388878572e-06 1.5707855116626381" xyz="0.0003906 3.121e-08 -0.014"/>
      <mass value="0.061"/>
      <inertia ixx="1.924000000025899e-05" ixy="0" ixz="0" iyy="1.709411627342488e-05" iyz="0" izz="5.9478837263161295e-06"/>
    </inertial>
    <visual>
      <origin rpy="-0.1443920950720977 1.9855029389503898e-05 1.5709191233325221" xyz="0.0018977016221143523 -1.0017682763976983e-06 -0.022983822146236326"/>
      <geometry>
        <mesh filename="../meshes/link_01.stl"/>
      </geometry>
      <material name="black"/>
    </visual>
    <collision>
      <origin rpy="-0.1443920950720977 1.9855029389503898e-05 1.5709191233325221" xyz="0.0018977016221143523 -1.0017682763976983e-06 -0.022983822146236326"/>
      <geometry>
        <mesh filename="../meshes/link_01.stl"/>
      </geometry>
    </collision>
  </link>
  <link name="leftF1_02">
    <inertial>
      <origin rpy="-0.0036890516412144943 0.31688564121750695 -0.0027736178951144786" xyz="0.01 3.444e-06 0.016"/>
      <mass value="0.025"/>
      <inertia ixx="7.164797732610912e-06" ixy="0" ixz="0" iyy="6.31301833122199e-06" iyz="0" izz="3.274183936167101e-06"/>
    </inertial>
    <visual>
      <origin rpy="-0.03118104794815292 0.3757385725887219 -0.024334342208719002" xyz="0.010322007813576017 0.000267674195662055 0.013590600703218703"/>
      <geometry>
        <mesh filename="../meshes/link_02.stl"/>
      </geometry>
      <material name="black"/>
    </visual>
    <collision>
      <origin rpy="-0.03118104794815292 0.3757385725887219 -0.024334342208719002" xyz="0.010322007813576017 0.000267674195662055 0.013590600703218703"/>
      <geometry>
        <mesh filename="../meshes/link_02.stl"/>
      </geometry>
    </collision>
  </link>
  <link name="leftF1_03">
    <inertial>
      <origin rpy="1.5651066808062148 -0.0008576993469346927 1.5562600280492769" xyz="0.014 -0.0004527 -3.953e-05"/>
      <mass value="0.051"/>
      <inertia ixx="1.6912201686125405e-05" ixy="0" ixz="0" iyy="1.4940271596370447e-05" iyz="0" izz="6.505526717504149e-06"/>
    </inertial>
    <visual>
      <origin rpy="1.5405533073968862 -0.0023628127138719535 1.5994547590929262" xyz="0.019034639558839914 -0.0007611783816217545 0.00015734818842133856"/>
      <geometry>
        <mesh filename="../meshes/link_03.stl"/>
      </geometry>
      <material name="black"/>
    </visual>
    <collision>
      <origin rpy="1.5405533073968862 -0.0023628127138719535 1.5994547590929262" xyz="0.019034639558839914 -0.0007611783816217545 0.00015734818842133856"/>
      <geometry>
        <mesh filename="../meshes/link_03.stl"/>
      </geometry>
    </collision>
  </link>
  <link name="leftF1_04">
    <inertial>
      <origin rpy="1.5668480451228681 -0.0008686188531681349 1.5829731507939977" xyz="0.012 -0.0002269 -4.676e-05"/>
      <mass value="0.058"/>
      <inertia ixx="1.0860820276783573e-05" ixy="0" ixz="0" iyy="9.902070548178027e-06" iyz="0" izz="5.330109175038405e-06"/>
    </inertial>
    <visual>
      <origin rpy="1.5745317514920234 0.003601150001683928 1.6650413701206925" xyz="0.011992289866897352 -0.0007726988011287212 -5.201111709052532e-06"/>
      <geometry>
        <mesh filename="../meshes/link_04.stl"/>
      </geometry>
      <material name="black"/>
    </visual>
    <collision>
      <origin rpy="1.5745317514920234 0.003601150001683928 1.6650413701206925" xyz="0.011992289866897352 -0.0007726988011287212 -5.201111709052532e-06"/>
      <geometry>
        <mesh filename="../meshes/link_04.stl"/>
      </geometry>
    </collision>
  </link>
  <link name="leftF1_TIP">
    <inertial>
      <origin rpy="1.5708008179564292 -3.695361794919805e-05 1.5210948927815267" xyz="0.045 -0.000436 -7.22e-08"/>
      <mass value="0.013"/>
      <inertia ixx="1.5965708653714455e-06" ixy="0" ixz="0" iyy="1.2999999996018677e-06" iyz="0" izz="9.60129135026688e-07"/>
    </inertial>
    <visual>
      <origin rpy="1.5708745579876908 -1.019986385419891e-05 1.5204133624130758" xyz="0.044959448417087294 -0.0004226309811080281 2.3018946871860735e-07"/>
      <geometry>
        <mesh filename="../meshes/link_tip_high.stl"/>
      </geometry>
      <material name="white"/>
    </visual>
    <collision>
      <origin rpy="1.5708745579876908 -1.019986385419891e-05 1.5204133624130758" xyz="0.044959448417087294 -0.0004226309811080281 2.3018946871860735e-07"/>
      <geometry>
        <mesh filename="../meshes/link_tip_high.stl"/>
      </geometry>
    </collision>
  </link>
  <link name="leftF2_01">
    <inertial>
      <origin rpy="-0.17662368646091148 -1.9303231388878572e-06 1.5707855116626381" xyz="0.0003906 3.121e-08 -0.014"/>
      <mass value="0.061"/>
      <inertia ixx="1.924000000025899e-05" ixy="0" ixz="0" iyy="1.709411627342488e-05" iyz="0" izz="5.9478837263161295e-06"/>
    </inertial>
    <visual>
      <origin rpy="-0.1443920950720977 1.9855029389503898e-05 1.5709191233325221" xyz="0.0018977016221143523 -1.0017682763976983e-06 -0.022983822146236326"/>
      <geometry>
        <mesh filename="../meshes/link_01.stl"/>
      </geometry>
      <material name="black"/>
    </visual>
    <collision>
      <origin rpy="-0.1443920950720977 1.9855029389503898e-05 1.5709191233325221" xyz="0.0018977016221143523 -1.0017682763976983e-06 -0.022983822146236326"/>
      <geometry>
        <mesh filename="../meshes/link_01.stl"/>
      </geometry>
    </collision>
  </link>
  <link name="leftF2_02">
    <inertial>
      <origin rpy="-0.0036890516412144943 0.31688564121750695 -0.0027736178951144786" xyz="0.01 3.444e-06 0.016"/>
      <mass value="0.025"/>
      <inertia ixx="7.164797732610912e-06" ixy="0" ixz="0" iyy="6.31301833122199e-06" iyz="0" izz="3.274183936167101e-06"/>
    </inertial>
    <visual>
      <origin rpy="-0.03118104794815292 0.3757385725887219 -0.024334342208719002" xyz="0.010322007813576017 0.000267674195662055 0.013590600703218703"/>
      <geometry>
        <mesh filename="../meshes/link_02.stl"/>
      </geometry>
      <material name="black"/>
    </visual>
    <collision>
      <origin rpy="-0.03118104794815292 0.3757385725887219 -0.024334342208719002" xyz="0.010322007813576017 0.000267674195662055 0.013590600703218703"/>
      <geometry>
        <mesh filename="../meshes/link_02.stl"/>
      </geometry>
    </collision>
  </link>
  <link name="leftF2_03">
    <inertial>
      <origin rpy="1.5651066808062148 -0.0008576993469346927 1.5562600280492769" xyz="0.014 -0.0004527 -3.953e-05"/>
      <mass value="0.051"/>
      <inertia ixx="1.6912201686125405e-05" ixy="0" ixz="0" iyy="1.4940271596370447e-05" iyz="0" izz="6.505526717504149e-06"/>
    </inertial>
    <visual>
      <origin rpy="1.5405533073968862 -0.0023628127138719535 1.5994547590929262" xyz="0.019034639558839914 -0.0007611783816217545 0.00015734818842133856"/>
      <geometry>
        <mesh filename="../meshes/link_03.stl"/>
      </geometry>
      <material name="black"/>
    </visual>
    <collision>
      <origin rpy="1.5405533073968862 -0.0023628127138719535 1.5994547590929262" xyz="0.019034639558839914 -0.0007611783816217545 0.00015734818842133856"/>
      <geometry>
        <mesh filename="../meshes/link_03.stl"/>
      </geometry>
    </collision>
  </link>
  <link name="leftF2_04">
    <inertial>
      <origin rpy="1.5668480451228681 -0.0008686188531681349 1.5829731507939977" xyz="0.012 -0.0002269 -4.676e-05"/>
      <mass value="0.058"/>
      <inertia ixx="1.0860820276783573e-05" ixy="0" ixz="0" iyy="9.902070548178027e-06" iyz="0" izz="5.330109175038405e-06"/>
    </inertial>
    <visual>
      <origin rpy="1.5745317514920234 0.003601150001683928 1.6650413701206925" xyz="0.011992289866897352 -0.0007726988011287212 -5.201111709052532e-06"/>
      <geometry>
        <mesh filename="../meshes/link_04.stl"/>
      </geometry>
      <material name="black"/>
    </visual>
    <collision>
      <origin rpy="1.5745317514920234 0.003601150001683928 1.6650413701206925" xyz="0.011992289866897352 -0.0007726988011287212 -5.201111709052532e-06"/>
      <geometry>
        <mesh filename="../meshes/link_04.stl"/>
      </geometry>
    </collision>
  </link>
  <link name="leftF2_TIP">
    <inertial>
      <origin rpy="1.5708008179564292 -3.695361794919805e-05 1.5210948927815267" xyz="0.045 -0.000436 -7.22e-08"/>
      <mass value="0.013"/>
      <inertia ixx="1.5965708653714455e-06" ixy="0" ixz="0" iyy="1.2999999996018677e-06" iyz="0" izz="9.60129135026688e-07"/>
    </inertial>
    <visual>
      <origin rpy="1.5708745579876908 -1.019986385419891e-05 1.5204133624130758" xyz="0.044959448417087294 -0.0004226309811080281 2.3018946871860735e-07"/>
      <geometry>
        <mesh filename="../meshes/link_tip_high.stl"/>
      </geometry>
      <material name="white"/>
    </visual>
    <collision>
      <origin rpy="1.5708745579876908 -1.019986385419891e-05 1.5204133624130758" xyz="0.044959448417087294 -0.0004226309811080281 2.3018946871860735e-07"/>
      <geometry>
        <mesh filename="../meshes/link_tip_high.stl"/>
      </geometry>
    </collision>
  </link>
  <link name="leftF3_01">
    <inertial>
      <origin rpy="-0.17662368646091148 -1.9303231388878572e-06 1.5707855116626381" xyz="0.0003906 3.121e-08 -0.014"/>
      <mass value="0.061"/>
      <inertia ixx="1.924000000025899e-05" ixy="0" ixz="0" iyy="1.709411627342488e-05" iyz="0" izz="5.9478837263161295e-06"/>
    </inertial>
    <visual>
      <origin rpy="-0.1443920950720977 1.9855029389503898e-05 1.5709191233325221" xyz="0.0018977016221143523 -1.0017682763976983e-06 -0.022983822146236326"/>
      <geometry>
        <mesh filename="../meshes/link_01.stl"/>
      </geometry>
      <material name="black"/>
    </visual>
    <collision>
      <origin rpy="-0.1443920950720977 1.9855029389503898e-05 1.5709191233325221" xyz="0.0018977016221143523 -1.0017682763976983e-06 -0.022983822146236326"/>
      <geometry>
        <mesh filename="../meshes/link_01.stl"/>
      </geometry>
    </collision>
  </link>
  <link name="leftF3_02">
    <inertial>
      <origin rpy="-0.0036890516412144943 0.31688564121750695 -0.0027736178951144786" xyz="0.01 3.444e-06 0.016"/>
      <mass value="0.025"/>
      <inertia ixx="7.164797732610912e-06" ixy="0" ixz="0" iyy="6.31301833122199e-06" iyz="0" izz="3.274183936167101e-06"/>
    </inertial>
    <visual>
      <origin rpy="-0.03118104794815292 0.3757385725887219 -0.024334342208719002" xyz="0.010322007813576017 0.000267674195662055 0.013590600703218703"/>
      <geometry>
        <mesh filename="../meshes/link_02.stl"/>
      </geometry>
      <material name="black"/>
    </visual>
    <collision>
      <origin rpy="-0.03118104794815292 0.3757385725887219 -0.024334342208719002" xyz="0.010322007813576017 0.000267674195662055 0.013590600703218703"/>
      <geometry>
        <mesh filename="../meshes/link_02.stl"/>
      </geometry>
    </collision>
  </link>
  <link name="leftF3_03">
    <inertial>
      <origin rpy="1.5651066808062148 -0.0008576993469346927 1.5562600280492769" xyz="0.014 -0.0004527 -3.953e-05"/>
      <mass value="0.051"/>
      <inertia ixx="1.6912201686125405e-05" ixy="0" ixz="0" iyy="1.4940271596370447e-05" iyz="0" izz="6.505526717504149e-06"/>
    </inertial>
    <visual>
      <origin rpy="1.5405533073968862 -0.0023628127138719535 1.5994547590929262" xyz="0.019034639558839914 -0.0007611783816217545 0.00015734818842133856"/>
      <geometry>
        <mesh filename="../meshes/link_03.stl"/>
      </geometry>
      <material name="black"/>
    </visual>
    <collision>
      <origin rpy="1.5405533073968862 -0.0023628127138719535 1.5994547590929262" xyz="0.019034639558839914 -0.0007611783816217545 0.00015734818842133856"/>
      <geometry>
        <mesh filename="../meshes/link_03.stl"/>
      </geometry>
    </collision>
  </link>
  <link name="leftF3_04">
    <inertial>
      <origin rpy="1.5668480451228681 -0.0008686188531681349 1.5829731507939977" xyz="0.012 -0.0002269 -4.676e-05"/>
      <mass value="0.058"/>
      <inertia ixx="1.0860820276783573e-05" ixy="0" ixz="0" iyy="9.902070548178027e-06" iyz="0" izz="5.330109175038405e-06"/>
    </inertial>
    <visual>
      <origin rpy="1.5745317514920234 0.003601150001683928 1.6650413701206925" xyz="0.011992289866897352 -0.0007726988011287212 -5.201111709052532e-06"/>
      <geometry>
        <mesh filename="../meshes/link_04.stl"/>
      </geometry>
      <material name="black"/>
    </visual>
    <collision>
      <origin rpy="1.5745317514920234 0.003601150001683928 1.6650413701206925" xyz="0.011992289866897352 -0.0007726988011287212 -5.201111709052532e-06"/>
      <geometry>
        <mesh filename="../meshes/link_04.stl"/>
      </geometry>
    </collision>
  </link>
  <link name="leftF3_TIP">
    <inertial>
      <origin rpy="1.5708008179564292 -3.695361794919805e-05 1.5210948927815267" xyz="0.045 -0.000436 -7.22e-08"/>
      <mass value="0.013"/>
      <inertia ixx="1.5965708653714455e-06" ixy="0" ixz="0" iyy="1.2999999996018677e-06" iyz="0" izz="9.60129135026688e-07"/>
    </inertial>
    <visual>
      <origin rpy="1.5708745579876908 -1.019986385419891e-05 1.5204133624130758" xyz="0.044959448417087294 -0.0004226309811080281 2.3018946871860735e-07"/>
      <geometry>
        <mesh filename="../meshes/link_tip_high.stl"/>
      </geometry>
      <material name="white"/>
    </visual>
    <collision>
      <origin rpy="1.5708745579876908 -1.019986385419891e-05 1.5204133624130758" xyz="0.044959448417087294 -0.0004226309811080281 2.3018946871860735e-07"/>
      <geometry>
        <mesh filename="../meshes/link_tip_high.stl"/>
      </geometry>
    </collision>
  </link>
</robot>

