<?xml version="1.0" ?>
<!-- =================================================================================== -->
<!-- |    This document was autogenerated by xacro from kortex_dual_robots.xacro       | -->
<!-- |    EDITING THIS FILE BY HAND IS NOT RECOMMENDED                                 | -->
<!-- =================================================================================== -->
<robot name="dual_robot">
 <mujoco>
    <compiler discardvisual="false"/>
  </mujoco>
  <material name="silver">
    <color rgba="0.700 0.700 0.700 1.000"/>
  </material>
  <material name="black">
    <color rgba="0.196 0.196 0.196 1.0"/>
  </material>
  <material name="white">
    <color rgba="1.0 1.0 1.0 1.0"/>
  </material>
  <link name="world"/>
  <joint name="world_to_left_root" type="fixed">
    <child link="left_base_link"/>
    <parent link="world"/>
    <!-- Here you can change the origin of the left arm-->
    <origin rpy=" 1.57 3.14 0" xyz=" 0 -0.25  1.4"/>
  </joint>
  <joint name="world_to_right_root" type="fixed">
    <child link="right_base_link"/>
    <parent link="world"/>
    <!-- Here you can change the origin of the right arm -->
    <origin rpy=" -1.57 0 0" xyz=" 0 0.25  1.4"/>
  </joint>
  <!-- 调用定义的 load_gripper 宏 -->
  <!-- <xacro:load_gripper parent="$(arg parent)" prefix="$(arg prefix)"/> -->
  <!-- Run the macros -->
  <link name="left_base_link">
    <inertial>
      <origin rpy="0 0 0" xyz="-0.000648 -0.000166 0.084487"/>
      <mass value="1.697"/>
      <inertia ixx="0.004622" ixy="9E-06" ixz="6E-05" iyy="0.004495" iyz="9E-06" izz="0.002079"/>
    </inertial>
    <visual>
      <origin rpy="0 0 0" xyz="0 0 0"/>
      <geometry>
        <mesh filename="package://kortex_description/arms/gen3/7dof/meshes/base_link.STL"/>
      </geometry>
      <material name="">
        <color rgba="0.75294 0.75294 0.75294 1"/>
      </material>
    </visual>
    <collision>
      <origin rpy="0 0 0" xyz="0 0 0"/>
      <geometry>
        <mesh filename="package://kortex_description/arms/gen3/7dof/meshes/base_link.STL"/>
      </geometry>
    </collision>
  </link>
  <link name="left_shoulder_link">
    <inertial>
      <origin rpy="0 0 0" xyz="-2.3E-05 -0.010364 -0.07336"/>
      <mass value="1.3773"/>
      <inertia ixx="0.00457" ixy="1E-06" ixz="2E-06" iyy="0.004831" iyz="0.000448" izz="0.001409"/>
    </inertial>
    <visual>
      <origin rpy="0 0 0" xyz="0 0 0"/>
      <geometry>
        <mesh filename="package://kortex_description/arms/gen3/7dof/meshes/shoulder_link.STL"/>
      </geometry>
      <material name="">
        <color rgba="0.75294 0.75294 0.75294 1"/>
      </material>
    </visual>
    <collision>
      <origin rpy="0 0 0" xyz="0 0 0"/>
      <geometry>
        <mesh filename="package://kortex_description/arms/gen3/7dof/meshes/shoulder_link.STL"/>
      </geometry>
    </collision>
  </link>
  <joint name="left_joint_1" type="continuous">
    <origin rpy="3.1416 2.7629E-18 -4.9305E-36" xyz="0 0 0.15643"/>
    <parent link="left_base_link"/>
    <child link="left_shoulder_link"/>
    <axis xyz="0 0 1"/>
    <limit effort="39" velocity="1.3963"/>
  </joint>
  <link name="left_half_arm_1_link">
    <inertial>
      <origin rpy="0 0 0" xyz="-4.4E-05 -0.09958 -0.013278"/>
      <mass value="1.1636"/>
      <inertia ixx="0.011088" ixy="5E-06" ixz="0" iyy="0.001072" iyz="-0.000691" izz="0.011255"/>
    </inertial>
    <visual>
      <origin rpy="0 0 0" xyz="0 0 0"/>
      <geometry>
        <mesh filename="package://kortex_description/arms/gen3/7dof/meshes/half_arm_1_link.STL"/>
      </geometry>
      <material name="">
        <color rgba="0.75294 0.75294 0.75294 1"/>
      </material>
    </visual>
    <collision>
      <origin rpy="0 0 0" xyz="0 0 0"/>
      <geometry>
        <mesh filename="package://kortex_description/arms/gen3/7dof/meshes/half_arm_1_link.STL"/>
      </geometry>
    </collision>
  </link>
  <joint name="left_joint_2" type="revolute">
    <origin rpy="1.5708 2.1343E-17 -1.1102E-16" xyz="0 0.005375 -0.12838"/>
    <parent link="left_shoulder_link"/>
    <child link="left_half_arm_1_link"/>
    <axis xyz="0 0 1"/>
    <limit effort="39" lower="-2.24" upper="2.24" velocity="1.3963"/>
  </joint>
  <link name="left_half_arm_2_link">
    <inertial>
      <origin rpy="0 0 0" xyz="-4.4E-05 -0.006641 -0.117892"/>
      <mass value="1.1636"/>
      <inertia ixx="0.010932" ixy="0" ixz="-7E-06" iyy="0.011127" iyz="0.000606" izz="0.001043"/>
    </inertial>
    <visual>
      <origin rpy="0 0 0" xyz="0 0 0"/>
      <geometry>
        <mesh filename="package://kortex_description/arms/gen3/7dof/meshes/half_arm_2_link.STL"/>
      </geometry>
      <material name="">
        <color rgba="0.75294 0.75294 0.75294 1"/>
      </material>
    </visual>
    <collision>
      <origin rpy="0 0 0" xyz="0 0 0"/>
      <geometry>
        <mesh filename="package://kortex_description/arms/gen3/7dof/meshes/half_arm_2_link.STL"/>
      </geometry>
    </collision>
  </link>
  <joint name="left_joint_3" type="continuous">
    <origin rpy="-1.5708 1.2326E-32 -2.9122E-16" xyz="0 -0.21038 -0.006375"/>
    <parent link="left_half_arm_1_link"/>
    <child link="left_half_arm_2_link"/>
    <axis xyz="0 0 1"/>
    <limit effort="39" velocity="1.3963"/>
  </joint>
  <link name="left_forearm_link">
    <inertial>
      <origin rpy="0 0 0" xyz="-1.8E-05 -0.075478 -0.015006"/>
      <mass value="0.9302"/>
      <inertia ixx="0.008147" ixy="-1E-06" ixz="0" iyy="0.000631" iyz="-0.0005" izz="0.008316"/>
    </inertial>
    <visual>
      <origin rpy="0 0 0" xyz="0 0 0"/>
      <geometry>
        <mesh filename="package://kortex_description/arms/gen3/7dof/meshes/forearm_link.STL"/>
      </geometry>
      <material name="">
        <color rgba="0.75294 0.75294 0.75294 1"/>
      </material>
    </visual>
    <collision>
      <origin rpy="0 0 0" xyz="0 0 0"/>
      <geometry>
        <mesh filename="package://kortex_description/arms/gen3/7dof/meshes/forearm_link.STL"/>
      </geometry>
    </collision>
  </link>
  <joint name="left_joint_4" type="revolute">
    <origin rpy="1.5708 -6.6954E-17 -1.6653E-16" xyz="0 0.006375 -0.21038"/>
    <parent link="left_half_arm_2_link"/>
    <child link="left_forearm_link"/>
    <axis xyz="0 0 1"/>
    <limit effort="39" lower="-2.57" upper="2.57" velocity="1.3963"/>
  </joint>
  <link name="left_spherical_wrist_1_link">
    <inertial>
      <origin rpy="0 0 0" xyz="1E-06 -0.009432 -0.063883"/>
      <mass value="0.6781"/>
      <inertia ixx="0.001596" ixy="0" ixz="0" iyy="0.001607" iyz="0.000256" izz="0.000399"/>
    </inertial>
    <visual>
      <origin rpy="0 0 0" xyz="0 0 0"/>
      <geometry>
        <mesh filename="package://kortex_description/arms/gen3/7dof/meshes/spherical_wrist_1_link.STL"/>
      </geometry>
      <material name="">
        <color rgba="0.75294 0.75294 0.75294 1"/>
      </material>
    </visual>
    <collision>
      <origin rpy="0 0 0" xyz="0 0 0"/>
      <geometry>
        <mesh filename="package://kortex_description/arms/gen3/7dof/meshes/spherical_wrist_1_link.STL"/>
      </geometry>
    </collision>
  </link>
  <joint name="left_joint_5" type="continuous">
    <origin rpy="-1.5708 2.2204E-16 -6.373E-17" xyz="0 -0.20843 -0.006375"/>
    <parent link="left_forearm_link"/>
    <child link="left_spherical_wrist_1_link"/>
    <axis xyz="0 0 1"/>
    <limit effort="9" velocity="1.2218"/>
  </joint>
  <link name="left_spherical_wrist_2_link">
    <inertial>
      <origin rpy="0 0 0" xyz="1E-06 -0.045483 -0.00965"/>
      <mass value="0.6781"/>
      <inertia ixx="0.001641" ixy="0" ixz="0" iyy="0.00041" iyz="-0.000278" izz="0.001641"/>
    </inertial>
    <visual>
      <origin rpy="0 0 0" xyz="0 0 0"/>
      <geometry>
        <mesh filename="package://kortex_description/arms/gen3/7dof/meshes/spherical_wrist_2_link.STL"/>
      </geometry>
      <material name="">
        <color rgba="0.75294 0.75294 0.75294 1"/>
      </material>
    </visual>
    <collision>
      <origin rpy="0 0 0" xyz="0 0 0"/>
      <geometry>
        <mesh filename="package://kortex_description/arms/gen3/7dof/meshes/spherical_wrist_2_link.STL"/>
      </geometry>
    </collision>
  </link>
  <joint name="left_joint_6" type="revolute">
    <origin rpy="1.5708 9.2076E-28 -8.2157E-15" xyz="0 0.00017505 -0.10593"/>
    <parent link="left_spherical_wrist_1_link"/>
    <child link="left_spherical_wrist_2_link"/>
    <axis xyz="0 0 1"/>
    <limit effort="9" lower="-2.09" upper="2.09" velocity="1.2218"/>
  </joint>
  <link name="left_bracelet_link">
    <inertial>
      <origin rpy="0 0 0" xyz="0.000281 0.011402 -0.029798"/>
      <mass value="0.5"/>
      <inertia ixx="0.000587" ixy="3E-06" ixz="3E-06" iyy="0.000369" iyz="-0.000118" izz="0.000609"/>
    </inertial>
    <visual>
      <origin rpy="0 0 0" xyz="0 0 0"/>
      <geometry>
        <mesh filename="package://kortex_description/arms/gen3/7dof/meshes/bracelet_with_vision_link.STL"/>
      </geometry>
      <material name="">
        <color rgba="0.75294 0.75294 0.75294 1"/>
      </material>
    </visual>
    <collision>
      <origin rpy="0 0 0" xyz="0 0 0"/>
      <geometry>
        <mesh filename="package://kortex_description/arms/gen3/7dof/meshes/bracelet_with_vision_link.STL"/>
      </geometry>
    </collision>
  </link>
  <joint name="left_joint_7" type="continuous">
    <origin rpy="-1.5708 -5.5511E-17 9.6396E-17" xyz="0 -0.10593 -0.00017505"/>
    <parent link="left_spherical_wrist_2_link"/>
    <child link="left_bracelet_link"/>
    <axis xyz="0 0 1"/>
    <limit effort="9" velocity="1.2218"/>
  </joint>
  <link name="left_end_effector_link"/>
  <joint name="left_end_effector" type="fixed">
    <origin rpy="3.14159265358979 1.09937075168372E-32 0" xyz="0 0 -0.0615250000000001"/>
    <parent link="left_bracelet_link"/>
    <child link="left_end_effector_link"/>
    <axis xyz="0 0 0"/>
  </joint>
  <link name="left_camera_link"/>
  <joint name="left_camera_module" type="fixed">
    <origin rpy="3.14159265358979 3.14159265358979 0" xyz="0 0.05639 -0.00305"/>
    <parent link="left_end_effector_link"/>
    <child link="left_camera_link"/>
  </joint>
  <link name="left_camera_depth_frame"/>
  <joint name="left_depth_module" type="fixed">
    <origin rpy="3.14159265358979 3.14159265358979 0" xyz="0.0275 0.066 -0.00305"/>
    <parent link="left_end_effector_link"/>
    <child link="left_camera_depth_frame"/>
  </joint>
  <link name="left_camera_color_frame"/>
  <joint name="left_color_module" type="fixed">
    <origin rpy="3.14159265358979 3.14159265358979 0" xyz="0 0.05639 -0.00305"/>
    <parent link="left_end_effector_link"/>
    <child link="left_camera_color_frame"/>
  </joint>
  <!--material -->
  <!-- <material name="silver">
        <color rgba="0.700 0.700 0.700 1.000"/>
    </material>

    <material name="black">
        <color rgba="0.196 0.196 0.196 1.0"/>
    </material>

    <material name="white">
        <color rgba="1.0 1.0 1.0 1.0"/>
    </material>  -->
  <!--link -->
  <!--Joint -->
  <!-- Tool frame used by the arm -->
  <link name="left_tool_frame"/>
  <joint name="left_tool_frame_joint" type="fixed">
    <origin rpy="0 0 0" xyz="0 0 0.20"/>
    <parent link="left_end_effector_link"/>
    <child link="left_tool_frame"/>
    <axis xyz="0 0 0"/>
  </joint>
  <!-- Gripper description -->
  <joint name="left_delto_3f_base_link" type="fixed">
    <parent link="left_end_effector_link"/>
    <child link="left_delto_base_link"/>
    <origin rpy="0.0 0.0 1.57" xyz="0.0 0.0 0.1"/>
  </joint>
  <link name="left_delto_base_link">
    <inertial>
      <origin rpy="5.671320207730568e-06 0.0032948722942074404 -0.00044870150924543735" xyz="0.00045499721796859983 -2.051648304165415e-06 -0.05218562175888181"/>
      <mass value="0.370"/>
      <inertia ixx="0.0009935903471030175" ixy="0" ixz="0" iyy="0.000980251548061173" iyz="0" izz="0.0003178199035240808"/>
    </inertial>
    <visual>
      <origin rpy="5.671320207730568e-06 0.0032948722942074404 -0.00044870150924543735" xyz="0.00045499721796859983 -2.051648304165415e-06 -0.05218562175888181"/>
      <geometry>
        <mesh filename="package://kortex_description/grippers/delto_3f/meshes/delto_base_link.stl"/>
      </geometry>
      <material name="black"/>
    </visual>
    <collision>
      <origin rpy="5.671320207730568e-06 0.0032948722942074404 -0.00044870150924543735" xyz="0.00045499721796859983 -2.051648304165415e-06 -0.05218562175888181"/>
      <geometry>
        <mesh filename="package://kortex_description/grippers/delto_3f/meshes/delto_base_link.stl"/>
      </geometry>
    </collision>
  </link>
   --&gt;
    
  <joint name="left_F1M1" type="revolute">
    <origin rpy="0 0 0" xyz="0.0265 0.0 0.0"/>
    <parent link="left_delto_base_link"/>
    <child link="left_F1_01"/>
    <axis xyz="0.0 0.0 1.0"/>
    <limit effort="10.0" lower="-1.0472" upper="1.0472" velocity="5.0"/>
    <dynamics damping="1.1" friction="1.1"/>
  </joint>
  <joint name="left_F1M2" type="revolute">
    <origin rpy="-3.1415926207728213 -1.570796290294655 0.0" xyz="0.0 0.0 0.0"/>
    <parent link="left_F1_01"/>
    <child link="left_F1_02"/>
    <axis xyz="0.0 0.0 1.0"/>
    <limit effort="10.0" lower="-1.76278" upper="1.76278" velocity="5.0"/>
    <dynamics damping="1.1" friction="1.1"/>
  </joint>
  <joint name="left_F1M3" type="revolute">
    <origin rpy="-1.5707963295583207 -1.5707963267948966 0.0" xyz="0.02022 0.0 0.03136"/>
    <parent link="left_F1_02"/>
    <child link="left_F1_03"/>
    <axis xyz="0.0 0.0 1.0"/>
    <limit effort="10.0" lower="-0.15708" upper="2.53073" velocity="5.0"/>
    <dynamics damping="1.1" friction="1.1"/>
  </joint>
  <joint name="left_F1M4" type="revolute">
    <origin rpy="0 0 0" xyz="0.0434 0.0 0.0"/>
    <parent link="left_F1_03"/>
    <child link="left_F1_04"/>
    <axis xyz="0.0 0.0 1.0"/>
    <limit effort="10.0" lower="-0.226893" upper="2.02458" velocity="5.0"/>
    <dynamics damping="1.1" friction="1.1"/>
  </joint>
  <joint name="left_TIP1" type="fixed">
    <origin rpy="0 0 0" xyz="0.0 0.0 0.0"/>
    <parent link="left_F1_04"/>
    <child link="left_F1_TIP"/>
  </joint>
  <joint name="left_F2M1" type="revolute">
    <origin rpy="0 0 -3.14" xyz="-0.01334 0.023 0.0"/>
    <parent link="left_delto_base_link"/>
    <child link="left_F2_01"/>
    <axis xyz="0.0 0.0 1.0"/>
    <limit effort="10.0" lower="-1.91986" upper="0.139626" velocity="5.0"/>
    <dynamics damping="1.1" friction="1.1"/>
  </joint>
  <joint name="left_F2M2" type="revolute">
    <origin rpy="-3.14 -1.57 0" xyz="0.0 0.0 0.0"/>
    <parent link="left_F2_01"/>
    <child link="left_F2_02"/>
    <axis xyz="0.0 0.0 1.0"/>
    <limit effort="10.0" lower="-1.76278" upper="1.76278" velocity="5.0"/>
    <dynamics damping="1.1" friction="1.1"/>
  </joint>
  <joint name="left_F2M3" type="revolute">
    <origin rpy="-1.57 -1.57 0" xyz="0.02022 0.0 0.03136"/>
    <parent link="left_F2_02"/>
    <child link="left_F2_03"/>
    <axis xyz="0.0 0.0 1.0"/>
    <limit effort="10.0" lower="-0.15708" upper="2.53073" velocity="5.0"/>
    <dynamics damping="1.1" friction="1.1"/>
  </joint>
  <joint name="left_F2M4" type="revolute">
    <origin rpy="0 0 0" xyz="0.0434 0.0 0.0"/>
    <parent link="left_F2_03"/>
    <child link="left_F2_04"/>
    <axis xyz="0.0434 0.0 1.0"/>
    <limit effort="10.0" lower="-0.226893" upper="2.02458" velocity="5.0"/>
    <dynamics damping="1.1" friction="1.1"/>
  </joint>
  <joint name="left_TIP2" type="fixed">
    <origin rpy="0 0 0" xyz="0.0 0.0 0.0"/>
    <parent link="left_F2_04"/>
    <child link="left_F2_TIP"/>
  </joint>
  <joint name="left_F3M1" type="revolute">
    <origin rpy="0 0 -3.14" xyz="-0.01334 -0.023 0.0"/>
    <parent link="left_delto_base_link"/>
    <child link="left_F3_01"/>
    <axis xyz=".0 0.0 1.0"/>
    <limit effort="10.0" lower="-0.0872665" upper="2.00713" velocity="5.0"/>
    <dynamics damping="1.1" friction="1.1"/>
  </joint>
  <joint name="left_F3M2" type="revolute">
    <origin rpy="-3.14 -1.57 0" xyz="0.0 0.0 0.0"/>
    <parent link="left_F3_01"/>
    <child link="left_F3_02"/>
    <axis xyz="0.0 0.0 1.0"/>
    <limit effort="10.0" lower="-1.76278" upper="1.76278" velocity="5.0"/>
    <dynamics damping="1.1" friction="1.1"/>
  </joint>
  <joint name="left_F3M3" type="revolute">
    <origin rpy="-1.57 -1.57 0" xyz="0.02022 0.0 0.03136"/>
    <parent link="left_F3_02"/>
    <child link="left_F3_03"/>
    <axis xyz="0.0 0.0 1.0"/>
    <limit effort="10.0" lower="-0.15708" upper="2.53073" velocity="5.0"/>
    <dynamics damping="1.1" friction="1.1"/>
  </joint>
  <joint name="left_F3M4" type="revolute">
    <origin rpy="0 0 0" xyz="0.0434 0.0 0.0"/>
    <parent link="left_F3_03"/>
    <child link="left_F3_04"/>
    <axis xyz="0.0 0.0 1.0"/>
    <limit effort="10.0" lower="-0.226893" upper="2.02458" velocity="5.0"/>
    <dynamics damping="1.1" friction="1.1"/>
  </joint>
  <joint name="left_TIP3" type="fixed">
    <origin rpy="0 0 0" xyz="0.0 0.0 0.0"/>
    <parent link="left_F3_04"/>
    <child link="left_F3_TIP"/>
  </joint>
  <link name="left_F1_01">
    <inertial>
      <origin rpy="-0.17662368646091148 -1.9303231388878572e-06 1.5707855116626381" xyz="0.0003906 3.121e-08 -0.014"/>
      <mass value="0.061"/>
      <inertia ixx="1.924000000025899e-05" ixy="0" ixz="0" iyy="1.709411627342488e-05" iyz="0" izz="5.9478837263161295e-06"/>
    </inertial>
    <visual>
      <origin rpy="-0.1443920950720977 1.9855029389503898e-05 1.5709191233325221" xyz="0.0018977016221143523 -1.0017682763976983e-06 -0.022983822146236326"/>
      <geometry>
        <mesh filename="package://kortex_description/grippers/delto_3f/meshes/link_01.stl"/>
      </geometry>
      <material name="black"/>
    </visual>
    <collision>
      <origin rpy="-0.1443920950720977 1.9855029389503898e-05 1.5709191233325221" xyz="0.0018977016221143523 -1.0017682763976983e-06 -0.022983822146236326"/>
      <geometry>
        <mesh filename="package://kortex_description/grippers/delto_3f/meshes/link_01.stl"/>
      </geometry>
    </collision>
  </link>
  <link name="left_F1_02">
    <inertial>
      <origin rpy="-0.0036890516412144943 0.31688564121750695 -0.0027736178951144786" xyz="0.01 3.444e-06 0.016"/>
      <mass value="0.025"/>
      <inertia ixx="7.164797732610912e-06" ixy="0" ixz="0" iyy="6.31301833122199e-06" iyz="0" izz="3.274183936167101e-06"/>
    </inertial>
    <visual>
      <origin rpy="-0.03118104794815292 0.3757385725887219 -0.024334342208719002" xyz="0.010322007813576017 0.000267674195662055 0.013590600703218703"/>
      <geometry>
        <mesh filename="package://kortex_description/grippers/delto_3f/meshes/link_02.stl"/>
      </geometry>
      <material name="black"/>
    </visual>
    <collision>
      <origin rpy="-0.03118104794815292 0.3757385725887219 -0.024334342208719002" xyz="0.010322007813576017 0.000267674195662055 0.013590600703218703"/>
      <geometry>
        <mesh filename="package://kortex_description/grippers/delto_3f/meshes/link_02.stl"/>
      </geometry>
    </collision>
  </link>
  <link name="left_F1_03">
    <inertial>
      <origin rpy="1.5651066808062148 -0.0008576993469346927 1.5562600280492769" xyz="0.014 -0.0004527 -3.953e-05"/>
      <mass value="0.051"/>
      <inertia ixx="1.6912201686125405e-05" ixy="0" ixz="0" iyy="1.4940271596370447e-05" iyz="0" izz="6.505526717504149e-06"/>
    </inertial>
    <visual>
      <origin rpy="1.5405533073968862 -0.0023628127138719535 1.5994547590929262" xyz="0.019034639558839914 -0.0007611783816217545 0.00015734818842133856"/>
      <geometry>
        <mesh filename="package://kortex_description/grippers/delto_3f/meshes/link_03.stl"/>
      </geometry>
      <material name="black"/>
    </visual>
    <collision>
      <origin rpy="1.5405533073968862 -0.0023628127138719535 1.5994547590929262" xyz="0.019034639558839914 -0.0007611783816217545 0.00015734818842133856"/>
      <geometry>
        <mesh filename="package://kortex_description/grippers/delto_3f/meshes/link_03.stl"/>
      </geometry>
    </collision>
  </link>
  <link name="left_F1_04">
    <inertial>
      <origin rpy="1.5668480451228681 -0.0008686188531681349 1.5829731507939977" xyz="0.012 -0.0002269 -4.676e-05"/>
      <mass value="0.058"/>
      <inertia ixx="1.0860820276783573e-05" ixy="0" ixz="0" iyy="9.902070548178027e-06" iyz="0" izz="5.330109175038405e-06"/>
    </inertial>
    <visual>
      <origin rpy="1.5745317514920234 0.003601150001683928 1.6650413701206925" xyz="0.011992289866897352 -0.0007726988011287212 -5.201111709052532e-06"/>
      <geometry>
        <mesh filename="package://kortex_description/grippers/delto_3f/meshes/link_04.stl"/>
      </geometry>
      <material name="black"/>
    </visual>
    <collision>
      <origin rpy="1.5745317514920234 0.003601150001683928 1.6650413701206925" xyz="0.011992289866897352 -0.0007726988011287212 -5.201111709052532e-06"/>
      <geometry>
        <mesh filename="package://kortex_description/grippers/delto_3f/meshes/link_04.stl"/>
      </geometry>
    </collision>
  </link>
  <link name="left_F1_TIP">
    <inertial>
      <origin rpy="1.5708008179564292 -3.695361794919805e-05 1.5210948927815267" xyz="0.045 -0.000436 -7.22e-08"/>
      <mass value="0.013"/>
      <inertia ixx="1.5965708653714455e-06" ixy="0" ixz="0" iyy="1.2999999996018677e-06" iyz="0" izz="9.60129135026688e-07"/>
    </inertial>
    <visual>
      <origin rpy="1.5708745579876908 -1.019986385419891e-05 1.5204133624130758" xyz="0.044959448417087294 -0.0004226309811080281 2.3018946871860735e-07"/>
      <geometry>
        <mesh filename="package://kortex_description/grippers/delto_3f/meshes/link_tip_high.stl"/>
      </geometry>
      <material name="white"/>
    </visual>
    <collision>
      <origin rpy="1.5708745579876908 -1.019986385419891e-05 1.5204133624130758" xyz="0.044959448417087294 -0.0004226309811080281 2.3018946871860735e-07"/>
      <geometry>
        <mesh filename="package://kortex_description/grippers/delto_3f/meshes/link_tip_high.stl"/>
      </geometry>
    </collision>
  </link>
  <link name="left_F2_01">
    <inertial>
      <origin rpy="-0.17662368646091148 -1.9303231388878572e-06 1.5707855116626381" xyz="0.0003906 3.121e-08 -0.014"/>
      <mass value="0.061"/>
      <inertia ixx="1.924000000025899e-05" ixy="0" ixz="0" iyy="1.709411627342488e-05" iyz="0" izz="5.9478837263161295e-06"/>
    </inertial>
    <visual>
      <origin rpy="-0.1443920950720977 1.9855029389503898e-05 1.5709191233325221" xyz="0.0018977016221143523 -1.0017682763976983e-06 -0.022983822146236326"/>
      <geometry>
        <mesh filename="package://kortex_description/grippers/delto_3f/meshes/link_01.stl"/>
      </geometry>
      <material name="black"/>
    </visual>
    <collision>
      <origin rpy="-0.1443920950720977 1.9855029389503898e-05 1.5709191233325221" xyz="0.0018977016221143523 -1.0017682763976983e-06 -0.022983822146236326"/>
      <geometry>
        <mesh filename="package://kortex_description/grippers/delto_3f/meshes/link_01.stl"/>
      </geometry>
    </collision>
  </link>
  <link name="left_F2_02">
    <inertial>
      <origin rpy="-0.0036890516412144943 0.31688564121750695 -0.0027736178951144786" xyz="0.01 3.444e-06 0.016"/>
      <mass value="0.025"/>
      <inertia ixx="7.164797732610912e-06" ixy="0" ixz="0" iyy="6.31301833122199e-06" iyz="0" izz="3.274183936167101e-06"/>
    </inertial>
    <visual>
      <origin rpy="-0.03118104794815292 0.3757385725887219 -0.024334342208719002" xyz="0.010322007813576017 0.000267674195662055 0.013590600703218703"/>
      <geometry>
        <mesh filename="package://kortex_description/grippers/delto_3f/meshes/link_02.stl"/>
      </geometry>
      <material name="black"/>
    </visual>
    <collision>
      <origin rpy="-0.03118104794815292 0.3757385725887219 -0.024334342208719002" xyz="0.010322007813576017 0.000267674195662055 0.013590600703218703"/>
      <geometry>
        <mesh filename="package://kortex_description/grippers/delto_3f/meshes/link_02.stl"/>
      </geometry>
    </collision>
  </link>
  <link name="left_F2_03">
    <inertial>
      <origin rpy="1.5651066808062148 -0.0008576993469346927 1.5562600280492769" xyz="0.014 -0.0004527 -3.953e-05"/>
      <mass value="0.051"/>
      <inertia ixx="1.6912201686125405e-05" ixy="0" ixz="0" iyy="1.4940271596370447e-05" iyz="0" izz="6.505526717504149e-06"/>
    </inertial>
    <visual>
      <origin rpy="1.5405533073968862 -0.0023628127138719535 1.5994547590929262" xyz="0.019034639558839914 -0.0007611783816217545 0.00015734818842133856"/>
      <geometry>
        <mesh filename="package://kortex_description/grippers/delto_3f/meshes/link_03.stl"/>
      </geometry>
      <material name="black"/>
    </visual>
    <collision>
      <origin rpy="1.5405533073968862 -0.0023628127138719535 1.5994547590929262" xyz="0.019034639558839914 -0.0007611783816217545 0.00015734818842133856"/>
      <geometry>
        <mesh filename="package://kortex_description/grippers/delto_3f/meshes/link_03.stl"/>
      </geometry>
    </collision>
  </link>
  <link name="left_F2_04">
    <inertial>
      <origin rpy="1.5668480451228681 -0.0008686188531681349 1.5829731507939977" xyz="0.012 -0.0002269 -4.676e-05"/>
      <mass value="0.058"/>
      <inertia ixx="1.0860820276783573e-05" ixy="0" ixz="0" iyy="9.902070548178027e-06" iyz="0" izz="5.330109175038405e-06"/>
    </inertial>
    <visual>
      <origin rpy="1.5745317514920234 0.003601150001683928 1.6650413701206925" xyz="0.011992289866897352 -0.0007726988011287212 -5.201111709052532e-06"/>
      <geometry>
        <mesh filename="package://kortex_description/grippers/delto_3f/meshes/link_04.stl"/>
      </geometry>
      <material name="black"/>
    </visual>
    <collision>
      <origin rpy="1.5745317514920234 0.003601150001683928 1.6650413701206925" xyz="0.011992289866897352 -0.0007726988011287212 -5.201111709052532e-06"/>
      <geometry>
        <mesh filename="package://kortex_description/grippers/delto_3f/meshes/link_04.stl"/>
      </geometry>
    </collision>
  </link>
  <link name="left_F2_TIP">
    <inertial>
      <origin rpy="1.5708008179564292 -3.695361794919805e-05 1.5210948927815267" xyz="0.045 -0.000436 -7.22e-08"/>
      <mass value="0.013"/>
      <inertia ixx="1.5965708653714455e-06" ixy="0" ixz="0" iyy="1.2999999996018677e-06" iyz="0" izz="9.60129135026688e-07"/>
    </inertial>
    <visual>
      <origin rpy="1.5708745579876908 -1.019986385419891e-05 1.5204133624130758" xyz="0.044959448417087294 -0.0004226309811080281 2.3018946871860735e-07"/>
      <geometry>
        <mesh filename="package://kortex_description/grippers/delto_3f/meshes/link_tip_high.stl"/>
      </geometry>
      <material name="white"/>
    </visual>
    <collision>
      <origin rpy="1.5708745579876908 -1.019986385419891e-05 1.5204133624130758" xyz="0.044959448417087294 -0.0004226309811080281 2.3018946871860735e-07"/>
      <geometry>
        <mesh filename="package://kortex_description/grippers/delto_3f/meshes/link_tip_high.stl"/>
      </geometry>
    </collision>
  </link>
  <link name="left_F3_01">
    <inertial>
      <origin rpy="-0.17662368646091148 -1.9303231388878572e-06 1.5707855116626381" xyz="0.0003906 3.121e-08 -0.014"/>
      <mass value="0.061"/>
      <inertia ixx="1.924000000025899e-05" ixy="0" ixz="0" iyy="1.709411627342488e-05" iyz="0" izz="5.9478837263161295e-06"/>
    </inertial>
    <visual>
      <origin rpy="-0.1443920950720977 1.9855029389503898e-05 1.5709191233325221" xyz="0.0018977016221143523 -1.0017682763976983e-06 -0.022983822146236326"/>
      <geometry>
        <mesh filename="package://kortex_description/grippers/delto_3f/meshes/link_01.stl"/>
      </geometry>
      <material name="black"/>
    </visual>
    <collision>
      <origin rpy="-0.1443920950720977 1.9855029389503898e-05 1.5709191233325221" xyz="0.0018977016221143523 -1.0017682763976983e-06 -0.022983822146236326"/>
      <geometry>
        <mesh filename="package://kortex_description/grippers/delto_3f/meshes/link_01.stl"/>
      </geometry>
    </collision>
  </link>
  <link name="left_F3_02">
    <inertial>
      <origin rpy="-0.0036890516412144943 0.31688564121750695 -0.0027736178951144786" xyz="0.01 3.444e-06 0.016"/>
      <mass value="0.025"/>
      <inertia ixx="7.164797732610912e-06" ixy="0" ixz="0" iyy="6.31301833122199e-06" iyz="0" izz="3.274183936167101e-06"/>
    </inertial>
    <visual>
      <origin rpy="-0.03118104794815292 0.3757385725887219 -0.024334342208719002" xyz="0.010322007813576017 0.000267674195662055 0.013590600703218703"/>
      <geometry>
        <mesh filename="package://kortex_description/grippers/delto_3f/meshes/link_02.stl"/>
      </geometry>
      <material name="black"/>
    </visual>
    <collision>
      <origin rpy="-0.03118104794815292 0.3757385725887219 -0.024334342208719002" xyz="0.010322007813576017 0.000267674195662055 0.013590600703218703"/>
      <geometry>
        <mesh filename="package://kortex_description/grippers/delto_3f/meshes/link_02.stl"/>
      </geometry>
    </collision>
  </link>
  <link name="left_F3_03">
    <inertial>
      <origin rpy="1.5651066808062148 -0.0008576993469346927 1.5562600280492769" xyz="0.014 -0.0004527 -3.953e-05"/>
      <mass value="0.051"/>
      <inertia ixx="1.6912201686125405e-05" ixy="0" ixz="0" iyy="1.4940271596370447e-05" iyz="0" izz="6.505526717504149e-06"/>
    </inertial>
    <visual>
      <origin rpy="1.5405533073968862 -0.0023628127138719535 1.5994547590929262" xyz="0.019034639558839914 -0.0007611783816217545 0.00015734818842133856"/>
      <geometry>
        <mesh filename="package://kortex_description/grippers/delto_3f/meshes/link_03.stl"/>
      </geometry>
      <material name="black"/>
    </visual>
    <collision>
      <origin rpy="1.5405533073968862 -0.0023628127138719535 1.5994547590929262" xyz="0.019034639558839914 -0.0007611783816217545 0.00015734818842133856"/>
      <geometry>
        <mesh filename="package://kortex_description/grippers/delto_3f/meshes/link_03.stl"/>
      </geometry>
    </collision>
  </link>
  <link name="left_F3_04">
    <inertial>
      <origin rpy="1.5668480451228681 -0.0008686188531681349 1.5829731507939977" xyz="0.012 -0.0002269 -4.676e-05"/>
      <mass value="0.058"/>
      <inertia ixx="1.0860820276783573e-05" ixy="0" ixz="0" iyy="9.902070548178027e-06" iyz="0" izz="5.330109175038405e-06"/>
    </inertial>
    <visual>
      <origin rpy="1.5745317514920234 0.003601150001683928 1.6650413701206925" xyz="0.011992289866897352 -0.0007726988011287212 -5.201111709052532e-06"/>
      <geometry>
        <mesh filename="package://kortex_description/grippers/delto_3f/meshes/link_04.stl"/>
      </geometry>
      <material name="black"/>
    </visual>
    <collision>
      <origin rpy="1.5745317514920234 0.003601150001683928 1.6650413701206925" xyz="0.011992289866897352 -0.0007726988011287212 -5.201111709052532e-06"/>
      <geometry>
        <mesh filename="package://kortex_description/grippers/delto_3f/meshes/link_04.stl"/>
      </geometry>
    </collision>
  </link>
  <link name="left_F3_TIP">
    <inertial>
      <origin rpy="1.5708008179564292 -3.695361794919805e-05 1.5210948927815267" xyz="0.045 -0.000436 -7.22e-08"/>
      <mass value="0.013"/>
      <inertia ixx="1.5965708653714455e-06" ixy="0" ixz="0" iyy="1.2999999996018677e-06" iyz="0" izz="9.60129135026688e-07"/>
    </inertial>
    <visual>
      <origin rpy="1.5708745579876908 -1.019986385419891e-05 1.5204133624130758" xyz="0.044959448417087294 -0.0004226309811080281 2.3018946871860735e-07"/>
      <geometry>
        <mesh filename="package://kortex_description/grippers/delto_3f/meshes/link_tip_high.stl"/>
      </geometry>
      <material name="white"/>
    </visual>
    <collision>
      <origin rpy="1.5708745579876908 -1.019986385419891e-05 1.5204133624130758" xyz="0.044959448417087294 -0.0004226309811080281 2.3018946871860735e-07"/>
      <geometry>
        <mesh filename="package://kortex_description/grippers/delto_3f/meshes/link_tip_high.stl"/>
      </geometry>
    </collision>
  </link>
  <!-- 调用定义的 load_gripper 宏 -->
  <!-- <xacro:load_gripper parent="$(arg parent)" prefix="$(arg prefix)"/> -->
  <!-- Run the macros -->
  <link name="right_base_link">
    <inertial>
      <origin rpy="0 0 0" xyz="-0.000648 -0.000166 0.084487"/>
      <mass value="1.697"/>
      <inertia ixx="0.004622" ixy="9E-06" ixz="6E-05" iyy="0.004495" iyz="9E-06" izz="0.002079"/>
    </inertial>
    <visual>
      <origin rpy="0 0 0" xyz="0 0 0"/>
      <geometry>
        <mesh filename="package://kortex_description/arms/gen3/7dof/meshes/base_link.STL"/>
      </geometry>
      <material name="">
        <color rgba="0.75294 0.75294 0.75294 1"/>
      </material>
    </visual>
    <collision>
      <origin rpy="0 0 0" xyz="0 0 0"/>
      <geometry>
        <mesh filename="package://kortex_description/arms/gen3/7dof/meshes/base_link.STL"/>
      </geometry>
    </collision>
  </link>
  <link name="right_shoulder_link">
    <inertial>
      <origin rpy="0 0 0" xyz="-2.3E-05 -0.010364 -0.07336"/>
      <mass value="1.3773"/>
      <inertia ixx="0.00457" ixy="1E-06" ixz="2E-06" iyy="0.004831" iyz="0.000448" izz="0.001409"/>
    </inertial>
    <visual>
      <origin rpy="0 0 0" xyz="0 0 0"/>
      <geometry>
        <mesh filename="package://kortex_description/arms/gen3/7dof/meshes/shoulder_link.STL"/>
      </geometry>
      <material name="">
        <color rgba="0.75294 0.75294 0.75294 1"/>
      </material>
    </visual>
    <collision>
      <origin rpy="0 0 0" xyz="0 0 0"/>
      <geometry>
        <mesh filename="package://kortex_description/arms/gen3/7dof/meshes/shoulder_link.STL"/>
      </geometry>
    </collision>
  </link>
  <joint name="right_joint_1" type="continuous">
    <origin rpy="3.1416 2.7629E-18 -4.9305E-36" xyz="0 0 0.15643"/>
    <parent link="right_base_link"/>
    <child link="right_shoulder_link"/>
    <axis xyz="0 0 1"/>
    <limit effort="39" velocity="1.3963"/>
  </joint>
  <link name="right_half_arm_1_link">
    <inertial>
      <origin rpy="0 0 0" xyz="-4.4E-05 -0.09958 -0.013278"/>
      <mass value="1.1636"/>
      <inertia ixx="0.011088" ixy="5E-06" ixz="0" iyy="0.001072" iyz="-0.000691" izz="0.011255"/>
    </inertial>
    <visual>
      <origin rpy="0 0 0" xyz="0 0 0"/>
      <geometry>
        <mesh filename="package://kortex_description/arms/gen3/7dof/meshes/half_arm_1_link.STL"/>
      </geometry>
      <material name="">
        <color rgba="0.75294 0.75294 0.75294 1"/>
      </material>
    </visual>
    <collision>
      <origin rpy="0 0 0" xyz="0 0 0"/>
      <geometry>
        <mesh filename="package://kortex_description/arms/gen3/7dof/meshes/half_arm_1_link.STL"/>
      </geometry>
    </collision>
  </link>
  <joint name="right_joint_2" type="revolute">
    <origin rpy="1.5708 2.1343E-17 -1.1102E-16" xyz="0 0.005375 -0.12838"/>
    <parent link="right_shoulder_link"/>
    <child link="right_half_arm_1_link"/>
    <axis xyz="0 0 1"/>
    <limit effort="39" lower="-2.24" upper="2.24" velocity="1.3963"/>
  </joint>
  <link name="right_half_arm_2_link">
    <inertial>
      <origin rpy="0 0 0" xyz="-4.4E-05 -0.006641 -0.117892"/>
      <mass value="1.1636"/>
      <inertia ixx="0.010932" ixy="0" ixz="-7E-06" iyy="0.011127" iyz="0.000606" izz="0.001043"/>
    </inertial>
    <visual>
      <origin rpy="0 0 0" xyz="0 0 0"/>
      <geometry>
        <mesh filename="package://kortex_description/arms/gen3/7dof/meshes/half_arm_2_link.STL"/>
      </geometry>
      <material name="">
        <color rgba="0.75294 0.75294 0.75294 1"/>
      </material>
    </visual>
    <collision>
      <origin rpy="0 0 0" xyz="0 0 0"/>
      <geometry>
        <mesh filename="package://kortex_description/arms/gen3/7dof/meshes/half_arm_2_link.STL"/>
      </geometry>
    </collision>
  </link>
  <joint name="right_joint_3" type="continuous">
    <origin rpy="-1.5708 1.2326E-32 -2.9122E-16" xyz="0 -0.21038 -0.006375"/>
    <parent link="right_half_arm_1_link"/>
    <child link="right_half_arm_2_link"/>
    <axis xyz="0 0 1"/>
    <limit effort="39" velocity="1.3963"/>
  </joint>
  <link name="right_forearm_link">
    <inertial>
      <origin rpy="0 0 0" xyz="-1.8E-05 -0.075478 -0.015006"/>
      <mass value="0.9302"/>
      <inertia ixx="0.008147" ixy="-1E-06" ixz="0" iyy="0.000631" iyz="-0.0005" izz="0.008316"/>
    </inertial>
    <visual>
      <origin rpy="0 0 0" xyz="0 0 0"/>
      <geometry>
        <mesh filename="package://kortex_description/arms/gen3/7dof/meshes/forearm_link.STL"/>
      </geometry>
      <material name="">
        <color rgba="0.75294 0.75294 0.75294 1"/>
      </material>
    </visual>
    <collision>
      <origin rpy="0 0 0" xyz="0 0 0"/>
      <geometry>
        <mesh filename="package://kortex_description/arms/gen3/7dof/meshes/forearm_link.STL"/>
      </geometry>
    </collision>
  </link>
  <joint name="right_joint_4" type="revolute">
    <origin rpy="1.5708 -6.6954E-17 -1.6653E-16" xyz="0 0.006375 -0.21038"/>
    <parent link="right_half_arm_2_link"/>
    <child link="right_forearm_link"/>
    <axis xyz="0 0 1"/>
    <limit effort="39" lower="-2.57" upper="2.57" velocity="1.3963"/>
  </joint>
  <link name="right_spherical_wrist_1_link">
    <inertial>
      <origin rpy="0 0 0" xyz="1E-06 -0.009432 -0.063883"/>
      <mass value="0.6781"/>
      <inertia ixx="0.001596" ixy="0" ixz="0" iyy="0.001607" iyz="0.000256" izz="0.000399"/>
    </inertial>
    <visual>
      <origin rpy="0 0 0" xyz="0 0 0"/>
      <geometry>
        <mesh filename="package://kortex_description/arms/gen3/7dof/meshes/spherical_wrist_1_link.STL"/>
      </geometry>
      <material name="">
        <color rgba="0.75294 0.75294 0.75294 1"/>
      </material>
    </visual>
    <collision>
      <origin rpy="0 0 0" xyz="0 0 0"/>
      <geometry>
        <mesh filename="package://kortex_description/arms/gen3/7dof/meshes/spherical_wrist_1_link.STL"/>
      </geometry>
    </collision>
  </link>
  <joint name="right_joint_5" type="continuous">
    <origin rpy="-1.5708 2.2204E-16 -6.373E-17" xyz="0 -0.20843 -0.006375"/>
    <parent link="right_forearm_link"/>
    <child link="right_spherical_wrist_1_link"/>
    <axis xyz="0 0 1"/>
    <limit effort="9" velocity="1.2218"/>
  </joint>
  <link name="right_spherical_wrist_2_link">
    <inertial>
      <origin rpy="0 0 0" xyz="1E-06 -0.045483 -0.00965"/>
      <mass value="0.6781"/>
      <inertia ixx="0.001641" ixy="0" ixz="0" iyy="0.00041" iyz="-0.000278" izz="0.001641"/>
    </inertial>
    <visual>
      <origin rpy="0 0 0" xyz="0 0 0"/>
      <geometry>
        <mesh filename="package://kortex_description/arms/gen3/7dof/meshes/spherical_wrist_2_link.STL"/>
      </geometry>
      <material name="">
        <color rgba="0.75294 0.75294 0.75294 1"/>
      </material>
    </visual>
    <collision>
      <origin rpy="0 0 0" xyz="0 0 0"/>
      <geometry>
        <mesh filename="package://kortex_description/arms/gen3/7dof/meshes/spherical_wrist_2_link.STL"/>
      </geometry>
    </collision>
  </link>
  <joint name="right_joint_6" type="revolute">
    <origin rpy="1.5708 9.2076E-28 -8.2157E-15" xyz="0 0.00017505 -0.10593"/>
    <parent link="right_spherical_wrist_1_link"/>
    <child link="right_spherical_wrist_2_link"/>
    <axis xyz="0 0 1"/>
    <limit effort="9" lower="-2.09" upper="2.09" velocity="1.2218"/>
  </joint>
  <link name="right_bracelet_link">
    <inertial>
      <origin rpy="0 0 0" xyz="0.000281 0.011402 -0.029798"/>
      <mass value="0.5"/>
      <inertia ixx="0.000587" ixy="3E-06" ixz="3E-06" iyy="0.000369" iyz="-0.000118" izz="0.000609"/>
    </inertial>
    <visual>
      <origin rpy="0 0 0" xyz="0 0 0"/>
      <geometry>
        <mesh filename="package://kortex_description/arms/gen3/7dof/meshes/bracelet_with_vision_link.STL"/>
      </geometry>
      <material name="">
        <color rgba="0.75294 0.75294 0.75294 1"/>
      </material>
    </visual>
    <collision>
      <origin rpy="0 0 0" xyz="0 0 0"/>
      <geometry>
        <mesh filename="package://kortex_description/arms/gen3/7dof/meshes/bracelet_with_vision_link.STL"/>
      </geometry>
    </collision>
  </link>
  <joint name="right_joint_7" type="continuous">
    <origin rpy="-1.5708 -5.5511E-17 9.6396E-17" xyz="0 -0.10593 -0.00017505"/>
    <parent link="right_spherical_wrist_2_link"/>
    <child link="right_bracelet_link"/>
    <axis xyz="0 0 1"/>
    <limit effort="9" velocity="1.2218"/>
  </joint>
  <link name="right_end_effector_link"/>
  <joint name="right_end_effector" type="fixed">
    <origin rpy="3.14159265358979 1.09937075168372E-32 0" xyz="0 0 -0.0615250000000001"/>
    <parent link="right_bracelet_link"/>
    <child link="right_end_effector_link"/>
    <axis xyz="0 0 0"/>
  </joint>
  <link name="right_camera_link"/>
  <joint name="right_camera_module" type="fixed">
    <origin rpy="3.14159265358979 3.14159265358979 0" xyz="0 0.05639 -0.00305"/>
    <parent link="right_end_effector_link"/>
    <child link="right_camera_link"/>
  </joint>
  <link name="right_camera_depth_frame"/>
  <joint name="right_depth_module" type="fixed">
    <origin rpy="3.14159265358979 3.14159265358979 0" xyz="0.0275 0.066 -0.00305"/>
    <parent link="right_end_effector_link"/>
    <child link="right_camera_depth_frame"/>
  </joint>
  <link name="right_camera_color_frame"/>
  <joint name="right_color_module" type="fixed">
    <origin rpy="3.14159265358979 3.14159265358979 0" xyz="0 0.05639 -0.00305"/>
    <parent link="right_end_effector_link"/>
    <child link="right_camera_color_frame"/>
  </joint>
  <!--material -->
  <!-- <material name="silver">
        <color rgba="0.700 0.700 0.700 1.000"/>
    </material>

    <material name="black">
        <color rgba="0.196 0.196 0.196 1.0"/>
    </material>

    <material name="white">
        <color rgba="1.0 1.0 1.0 1.0"/>
    </material>  -->
  <!--link -->
  <!--Joint -->
  <!-- Tool frame used by the arm -->
  <link name="right_tool_frame"/>
  <joint name="right_tool_frame_joint" type="fixed">
    <origin rpy="0 0 0" xyz="0 0 0.20"/>
    <parent link="right_end_effector_link"/>
    <child link="right_tool_frame"/>
    <axis xyz="0 0 0"/>
  </joint>
  <!-- Gripper description -->
  <joint name="right_delto_3f_base_link" type="fixed">
    <parent link="right_end_effector_link"/>
    <child link="right_delto_base_link"/>
    <origin rpy="0.0 0.0 1.57" xyz="0.0 0.0 0.1"/>
  </joint>
  <link name="right_delto_base_link">
    <inertial>
      <origin rpy="5.671320207730568e-06 0.0032948722942074404 -0.00044870150924543735" xyz="0.00045499721796859983 -2.051648304165415e-06 -0.05218562175888181"/>
      <mass value="0.370"/>
      <inertia ixx="0.0009935903471030175" ixy="0" ixz="0" iyy="0.000980251548061173" iyz="0" izz="0.0003178199035240808"/>
    </inertial>
    <visual>
      <origin rpy="5.671320207730568e-06 0.0032948722942074404 -0.00044870150924543735" xyz="0.00045499721796859983 -2.051648304165415e-06 -0.05218562175888181"/>
      <geometry>
        <mesh filename="package://kortex_description/grippers/delto_3f/meshes/delto_base_link.stl"/>
      </geometry>
      <material name="black"/>
    </visual>
    <collision>
      <origin rpy="5.671320207730568e-06 0.0032948722942074404 -0.00044870150924543735" xyz="0.00045499721796859983 -2.051648304165415e-06 -0.05218562175888181"/>
      <geometry>
        <mesh filename="package://kortex_description/grippers/delto_3f/meshes/delto_base_link.stl"/>
      </geometry>
    </collision>
  </link>
   --&gt;
    
  <joint name="right_F1M1" type="revolute">
    <origin rpy="0 0 0" xyz="0.0265 0.0 0.0"/>
    <parent link="right_delto_base_link"/>
    <child link="right_F1_01"/>
    <axis xyz="0.0 0.0 1.0"/>
    <limit effort="10.0" lower="-1.0472" upper="1.0472" velocity="5.0"/>
    <dynamics damping="1.1" friction="1.1"/>
  </joint>
  <joint name="right_F1M2" type="revolute">
    <origin rpy="-3.1415926207728213 -1.570796290294655 0.0" xyz="0.0 0.0 0.0"/>
    <parent link="right_F1_01"/>
    <child link="right_F1_02"/>
    <axis xyz="0.0 0.0 1.0"/>
    <limit effort="10.0" lower="-1.76278" upper="1.76278" velocity="5.0"/>
    <dynamics damping="1.1" friction="1.1"/>
  </joint>
  <joint name="right_F1M3" type="revolute">
    <origin rpy="-1.5707963295583207 -1.5707963267948966 0.0" xyz="0.02022 0.0 0.03136"/>
    <parent link="right_F1_02"/>
    <child link="right_F1_03"/>
    <axis xyz="0.0 0.0 1.0"/>
    <limit effort="10.0" lower="-0.15708" upper="2.53073" velocity="5.0"/>
    <dynamics damping="1.1" friction="1.1"/>
  </joint>
  <joint name="right_F1M4" type="revolute">
    <origin rpy="0 0 0" xyz="0.0434 0.0 0.0"/>
    <parent link="right_F1_03"/>
    <child link="right_F1_04"/>
    <axis xyz="0.0 0.0 1.0"/>
    <limit effort="10.0" lower="-0.226893" upper="2.02458" velocity="5.0"/>
    <dynamics damping="1.1" friction="1.1"/>
  </joint>
  <joint name="right_TIP1" type="fixed">
    <origin rpy="0 0 0" xyz="0.0 0.0 0.0"/>
    <parent link="right_F1_04"/>
    <child link="right_F1_TIP"/>
  </joint>
  <joint name="right_F2M1" type="revolute">
    <origin rpy="0 0 -3.14" xyz="-0.01334 0.023 0.0"/>
    <parent link="right_delto_base_link"/>
    <child link="right_F2_01"/>
    <axis xyz="0.0 0.0 1.0"/>
    <limit effort="10.0" lower="-1.91986" upper="0.139626" velocity="5.0"/>
    <dynamics damping="1.1" friction="1.1"/>
  </joint>
  <joint name="right_F2M2" type="revolute">
    <origin rpy="-3.14 -1.57 0" xyz="0.0 0.0 0.0"/>
    <parent link="right_F2_01"/>
    <child link="right_F2_02"/>
    <axis xyz="0.0 0.0 1.0"/>
    <limit effort="10.0" lower="-1.76278" upper="1.76278" velocity="5.0"/>
    <dynamics damping="1.1" friction="1.1"/>
  </joint>
  <joint name="right_F2M3" type="revolute">
    <origin rpy="-1.57 -1.57 0" xyz="0.02022 0.0 0.03136"/>
    <parent link="right_F2_02"/>
    <child link="right_F2_03"/>
    <axis xyz="0.0 0.0 1.0"/>
    <limit effort="10.0" lower="-0.15708" upper="2.53073" velocity="5.0"/>
    <dynamics damping="1.1" friction="1.1"/>
  </joint>
  <joint name="right_F2M4" type="revolute">
    <origin rpy="0 0 0" xyz="0.0434 0.0 0.0"/>
    <parent link="right_F2_03"/>
    <child link="right_F2_04"/>
    <axis xyz="0.0434 0.0 1.0"/>
    <limit effort="10.0" lower="-0.226893" upper="2.02458" velocity="5.0"/>
    <dynamics damping="1.1" friction="1.1"/>
  </joint>
  <joint name="right_TIP2" type="fixed">
    <origin rpy="0 0 0" xyz="0.0 0.0 0.0"/>
    <parent link="right_F2_04"/>
    <child link="right_F2_TIP"/>
  </joint>
  <joint name="right_F3M1" type="revolute">
    <origin rpy="0 0 -3.14" xyz="-0.01334 -0.023 0.0"/>
    <parent link="right_delto_base_link"/>
    <child link="right_F3_01"/>
    <axis xyz=".0 0.0 1.0"/>
    <limit effort="10.0" lower="-0.0872665" upper="2.00713" velocity="5.0"/>
    <dynamics damping="1.1" friction="1.1"/>
  </joint>
  <joint name="right_F3M2" type="revolute">
    <origin rpy="-3.14 -1.57 0" xyz="0.0 0.0 0.0"/>
    <parent link="right_F3_01"/>
    <child link="right_F3_02"/>
    <axis xyz="0.0 0.0 1.0"/>
    <limit effort="10.0" lower="-1.76278" upper="1.76278" velocity="5.0"/>
    <dynamics damping="1.1" friction="1.1"/>
  </joint>
  <joint name="right_F3M3" type="revolute">
    <origin rpy="-1.57 -1.57 0" xyz="0.02022 0.0 0.03136"/>
    <parent link="right_F3_02"/>
    <child link="right_F3_03"/>
    <axis xyz="0.0 0.0 1.0"/>
    <limit effort="10.0" lower="-0.15708" upper="2.53073" velocity="5.0"/>
    <dynamics damping="1.1" friction="1.1"/>
  </joint>
  <joint name="right_F3M4" type="revolute">
    <origin rpy="0 0 0" xyz="0.0434 0.0 0.0"/>
    <parent link="right_F3_03"/>
    <child link="right_F3_04"/>
    <axis xyz="0.0 0.0 1.0"/>
    <limit effort="10.0" lower="-0.226893" upper="2.02458" velocity="5.0"/>
    <dynamics damping="1.1" friction="1.1"/>
  </joint>
  <joint name="right_TIP3" type="fixed">
    <origin rpy="0 0 0" xyz="0.0 0.0 0.0"/>
    <parent link="right_F3_04"/>
    <child link="right_F3_TIP"/>
  </joint>
  <link name="right_F1_01">
    <inertial>
      <origin rpy="-0.17662368646091148 -1.9303231388878572e-06 1.5707855116626381" xyz="0.0003906 3.121e-08 -0.014"/>
      <mass value="0.061"/>
      <inertia ixx="1.924000000025899e-05" ixy="0" ixz="0" iyy="1.709411627342488e-05" iyz="0" izz="5.9478837263161295e-06"/>
    </inertial>
    <visual>
      <origin rpy="-0.1443920950720977 1.9855029389503898e-05 1.5709191233325221" xyz="0.0018977016221143523 -1.0017682763976983e-06 -0.022983822146236326"/>
      <geometry>
        <mesh filename="package://kortex_description/grippers/delto_3f/meshes/link_01.stl"/>
      </geometry>
      <material name="black"/>
    </visual>
    <collision>
      <origin rpy="-0.1443920950720977 1.9855029389503898e-05 1.5709191233325221" xyz="0.0018977016221143523 -1.0017682763976983e-06 -0.022983822146236326"/>
      <geometry>
        <mesh filename="package://kortex_description/grippers/delto_3f/meshes/link_01.stl"/>
      </geometry>
    </collision>
  </link>
  <link name="right_F1_02">
    <inertial>
      <origin rpy="-0.0036890516412144943 0.31688564121750695 -0.0027736178951144786" xyz="0.01 3.444e-06 0.016"/>
      <mass value="0.025"/>
      <inertia ixx="7.164797732610912e-06" ixy="0" ixz="0" iyy="6.31301833122199e-06" iyz="0" izz="3.274183936167101e-06"/>
    </inertial>
    <visual>
      <origin rpy="-0.03118104794815292 0.3757385725887219 -0.024334342208719002" xyz="0.010322007813576017 0.000267674195662055 0.013590600703218703"/>
      <geometry>
        <mesh filename="package://kortex_description/grippers/delto_3f/meshes/link_02.stl"/>
      </geometry>
      <material name="black"/>
    </visual>
    <collision>
      <origin rpy="-0.03118104794815292 0.3757385725887219 -0.024334342208719002" xyz="0.010322007813576017 0.000267674195662055 0.013590600703218703"/>
      <geometry>
        <mesh filename="package://kortex_description/grippers/delto_3f/meshes/link_02.stl"/>
      </geometry>
    </collision>
  </link>
  <link name="right_F1_03">
    <inertial>
      <origin rpy="1.5651066808062148 -0.0008576993469346927 1.5562600280492769" xyz="0.014 -0.0004527 -3.953e-05"/>
      <mass value="0.051"/>
      <inertia ixx="1.6912201686125405e-05" ixy="0" ixz="0" iyy="1.4940271596370447e-05" iyz="0" izz="6.505526717504149e-06"/>
    </inertial>
    <visual>
      <origin rpy="1.5405533073968862 -0.0023628127138719535 1.5994547590929262" xyz="0.019034639558839914 -0.0007611783816217545 0.00015734818842133856"/>
      <geometry>
        <mesh filename="package://kortex_description/grippers/delto_3f/meshes/link_03.stl"/>
      </geometry>
      <material name="black"/>
    </visual>
    <collision>
      <origin rpy="1.5405533073968862 -0.0023628127138719535 1.5994547590929262" xyz="0.019034639558839914 -0.0007611783816217545 0.00015734818842133856"/>
      <geometry>
        <mesh filename="package://kortex_description/grippers/delto_3f/meshes/link_03.stl"/>
      </geometry>
    </collision>
  </link>
  <link name="right_F1_04">
    <inertial>
      <origin rpy="1.5668480451228681 -0.0008686188531681349 1.5829731507939977" xyz="0.012 -0.0002269 -4.676e-05"/>
      <mass value="0.058"/>
      <inertia ixx="1.0860820276783573e-05" ixy="0" ixz="0" iyy="9.902070548178027e-06" iyz="0" izz="5.330109175038405e-06"/>
    </inertial>
    <visual>
      <origin rpy="1.5745317514920234 0.003601150001683928 1.6650413701206925" xyz="0.011992289866897352 -0.0007726988011287212 -5.201111709052532e-06"/>
      <geometry>
        <mesh filename="package://kortex_description/grippers/delto_3f/meshes/link_04.stl"/>
      </geometry>
      <material name="black"/>
    </visual>
    <collision>
      <origin rpy="1.5745317514920234 0.003601150001683928 1.6650413701206925" xyz="0.011992289866897352 -0.0007726988011287212 -5.201111709052532e-06"/>
      <geometry>
        <mesh filename="package://kortex_description/grippers/delto_3f/meshes/link_04.stl"/>
      </geometry>
    </collision>
  </link>
  <link name="right_F1_TIP">
    <inertial>
      <origin rpy="1.5708008179564292 -3.695361794919805e-05 1.5210948927815267" xyz="0.045 -0.000436 -7.22e-08"/>
      <mass value="0.013"/>
      <inertia ixx="1.5965708653714455e-06" ixy="0" ixz="0" iyy="1.2999999996018677e-06" iyz="0" izz="9.60129135026688e-07"/>
    </inertial>
    <visual>
      <origin rpy="1.5708745579876908 -1.019986385419891e-05 1.5204133624130758" xyz="0.044959448417087294 -0.0004226309811080281 2.3018946871860735e-07"/>
      <geometry>
        <mesh filename="package://kortex_description/grippers/delto_3f/meshes/link_tip_high.stl"/>
      </geometry>
      <material name="white"/>
    </visual>
    <collision>
      <origin rpy="1.5708745579876908 -1.019986385419891e-05 1.5204133624130758" xyz="0.044959448417087294 -0.0004226309811080281 2.3018946871860735e-07"/>
      <geometry>
        <mesh filename="package://kortex_description/grippers/delto_3f/meshes/link_tip_high.stl"/>
      </geometry>
    </collision>
  </link>
  <link name="right_F2_01">
    <inertial>
      <origin rpy="-0.17662368646091148 -1.9303231388878572e-06 1.5707855116626381" xyz="0.0003906 3.121e-08 -0.014"/>
      <mass value="0.061"/>
      <inertia ixx="1.924000000025899e-05" ixy="0" ixz="0" iyy="1.709411627342488e-05" iyz="0" izz="5.9478837263161295e-06"/>
    </inertial>
    <visual>
      <origin rpy="-0.1443920950720977 1.9855029389503898e-05 1.5709191233325221" xyz="0.0018977016221143523 -1.0017682763976983e-06 -0.022983822146236326"/>
      <geometry>
        <mesh filename="package://kortex_description/grippers/delto_3f/meshes/link_01.stl"/>
      </geometry>
      <material name="black"/>
    </visual>
    <collision>
      <origin rpy="-0.1443920950720977 1.9855029389503898e-05 1.5709191233325221" xyz="0.0018977016221143523 -1.0017682763976983e-06 -0.022983822146236326"/>
      <geometry>
        <mesh filename="package://kortex_description/grippers/delto_3f/meshes/link_01.stl"/>
      </geometry>
    </collision>
  </link>
  <link name="right_F2_02">
    <inertial>
      <origin rpy="-0.0036890516412144943 0.31688564121750695 -0.0027736178951144786" xyz="0.01 3.444e-06 0.016"/>
      <mass value="0.025"/>
      <inertia ixx="7.164797732610912e-06" ixy="0" ixz="0" iyy="6.31301833122199e-06" iyz="0" izz="3.274183936167101e-06"/>
    </inertial>
    <visual>
      <origin rpy="-0.03118104794815292 0.3757385725887219 -0.024334342208719002" xyz="0.010322007813576017 0.000267674195662055 0.013590600703218703"/>
      <geometry>
        <mesh filename="package://kortex_description/grippers/delto_3f/meshes/link_02.stl"/>
      </geometry>
      <material name="black"/>
    </visual>
    <collision>
      <origin rpy="-0.03118104794815292 0.3757385725887219 -0.024334342208719002" xyz="0.010322007813576017 0.000267674195662055 0.013590600703218703"/>
      <geometry>
        <mesh filename="package://kortex_description/grippers/delto_3f/meshes/link_02.stl"/>
      </geometry>
    </collision>
  </link>
  <link name="right_F2_03">
    <inertial>
      <origin rpy="1.5651066808062148 -0.0008576993469346927 1.5562600280492769" xyz="0.014 -0.0004527 -3.953e-05"/>
      <mass value="0.051"/>
      <inertia ixx="1.6912201686125405e-05" ixy="0" ixz="0" iyy="1.4940271596370447e-05" iyz="0" izz="6.505526717504149e-06"/>
    </inertial>
    <visual>
      <origin rpy="1.5405533073968862 -0.0023628127138719535 1.5994547590929262" xyz="0.019034639558839914 -0.0007611783816217545 0.00015734818842133856"/>
      <geometry>
        <mesh filename="package://kortex_description/grippers/delto_3f/meshes/link_03.stl"/>
      </geometry>
      <material name="black"/>
    </visual>
    <collision>
      <origin rpy="1.5405533073968862 -0.0023628127138719535 1.5994547590929262" xyz="0.019034639558839914 -0.0007611783816217545 0.00015734818842133856"/>
      <geometry>
        <mesh filename="package://kortex_description/grippers/delto_3f/meshes/link_03.stl"/>
      </geometry>
    </collision>
  </link>
  <link name="right_F2_04">
    <inertial>
      <origin rpy="1.5668480451228681 -0.0008686188531681349 1.5829731507939977" xyz="0.012 -0.0002269 -4.676e-05"/>
      <mass value="0.058"/>
      <inertia ixx="1.0860820276783573e-05" ixy="0" ixz="0" iyy="9.902070548178027e-06" iyz="0" izz="5.330109175038405e-06"/>
    </inertial>
    <visual>
      <origin rpy="1.5745317514920234 0.003601150001683928 1.6650413701206925" xyz="0.011992289866897352 -0.0007726988011287212 -5.201111709052532e-06"/>
      <geometry>
        <mesh filename="package://kortex_description/grippers/delto_3f/meshes/link_04.stl"/>
      </geometry>
      <material name="black"/>
    </visual>
    <collision>
      <origin rpy="1.5745317514920234 0.003601150001683928 1.6650413701206925" xyz="0.011992289866897352 -0.0007726988011287212 -5.201111709052532e-06"/>
      <geometry>
        <mesh filename="package://kortex_description/grippers/delto_3f/meshes/link_04.stl"/>
      </geometry>
    </collision>
  </link>
  <link name="right_F2_TIP">
    <inertial>
      <origin rpy="1.5708008179564292 -3.695361794919805e-05 1.5210948927815267" xyz="0.045 -0.000436 -7.22e-08"/>
      <mass value="0.013"/>
      <inertia ixx="1.5965708653714455e-06" ixy="0" ixz="0" iyy="1.2999999996018677e-06" iyz="0" izz="9.60129135026688e-07"/>
    </inertial>
    <visual>
      <origin rpy="1.5708745579876908 -1.019986385419891e-05 1.5204133624130758" xyz="0.044959448417087294 -0.0004226309811080281 2.3018946871860735e-07"/>
      <geometry>
        <mesh filename="package://kortex_description/grippers/delto_3f/meshes/link_tip_high.stl"/>
      </geometry>
      <material name="white"/>
    </visual>
    <collision>
      <origin rpy="1.5708745579876908 -1.019986385419891e-05 1.5204133624130758" xyz="0.044959448417087294 -0.0004226309811080281 2.3018946871860735e-07"/>
      <geometry>
        <mesh filename="package://kortex_description/grippers/delto_3f/meshes/link_tip_high.stl"/>
      </geometry>
    </collision>
  </link>
  <link name="right_F3_01">
    <inertial>
      <origin rpy="-0.17662368646091148 -1.9303231388878572e-06 1.5707855116626381" xyz="0.0003906 3.121e-08 -0.014"/>
      <mass value="0.061"/>
      <inertia ixx="1.924000000025899e-05" ixy="0" ixz="0" iyy="1.709411627342488e-05" iyz="0" izz="5.9478837263161295e-06"/>
    </inertial>
    <visual>
      <origin rpy="-0.1443920950720977 1.9855029389503898e-05 1.5709191233325221" xyz="0.0018977016221143523 -1.0017682763976983e-06 -0.022983822146236326"/>
      <geometry>
        <mesh filename="package://kortex_description/grippers/delto_3f/meshes/link_01.stl"/>
      </geometry>
      <material name="black"/>
    </visual>
    <collision>
      <origin rpy="-0.1443920950720977 1.9855029389503898e-05 1.5709191233325221" xyz="0.0018977016221143523 -1.0017682763976983e-06 -0.022983822146236326"/>
      <geometry>
        <mesh filename="package://kortex_description/grippers/delto_3f/meshes/link_01.stl"/>
      </geometry>
    </collision>
  </link>
  <link name="right_F3_02">
    <inertial>
      <origin rpy="-0.0036890516412144943 0.31688564121750695 -0.0027736178951144786" xyz="0.01 3.444e-06 0.016"/>
      <mass value="0.025"/>
      <inertia ixx="7.164797732610912e-06" ixy="0" ixz="0" iyy="6.31301833122199e-06" iyz="0" izz="3.274183936167101e-06"/>
    </inertial>
    <visual>
      <origin rpy="-0.03118104794815292 0.3757385725887219 -0.024334342208719002" xyz="0.010322007813576017 0.000267674195662055 0.013590600703218703"/>
      <geometry>
        <mesh filename="package://kortex_description/grippers/delto_3f/meshes/link_02.stl"/>
      </geometry>
      <material name="black"/>
    </visual>
    <collision>
      <origin rpy="-0.03118104794815292 0.3757385725887219 -0.024334342208719002" xyz="0.010322007813576017 0.000267674195662055 0.013590600703218703"/>
      <geometry>
        <mesh filename="package://kortex_description/grippers/delto_3f/meshes/link_02.stl"/>
      </geometry>
    </collision>
  </link>
  <link name="right_F3_03">
    <inertial>
      <origin rpy="1.5651066808062148 -0.0008576993469346927 1.5562600280492769" xyz="0.014 -0.0004527 -3.953e-05"/>
      <mass value="0.051"/>
      <inertia ixx="1.6912201686125405e-05" ixy="0" ixz="0" iyy="1.4940271596370447e-05" iyz="0" izz="6.505526717504149e-06"/>
    </inertial>
    <visual>
      <origin rpy="1.5405533073968862 -0.0023628127138719535 1.5994547590929262" xyz="0.019034639558839914 -0.0007611783816217545 0.00015734818842133856"/>
      <geometry>
        <mesh filename="package://kortex_description/grippers/delto_3f/meshes/link_03.stl"/>
      </geometry>
      <material name="black"/>
    </visual>
    <collision>
      <origin rpy="1.5405533073968862 -0.0023628127138719535 1.5994547590929262" xyz="0.019034639558839914 -0.0007611783816217545 0.00015734818842133856"/>
      <geometry>
        <mesh filename="package://kortex_description/grippers/delto_3f/meshes/link_03.stl"/>
      </geometry>
    </collision>
  </link>
  <link name="right_F3_04">
    <inertial>
      <origin rpy="1.5668480451228681 -0.0008686188531681349 1.5829731507939977" xyz="0.012 -0.0002269 -4.676e-05"/>
      <mass value="0.058"/>
      <inertia ixx="1.0860820276783573e-05" ixy="0" ixz="0" iyy="9.902070548178027e-06" iyz="0" izz="5.330109175038405e-06"/>
    </inertial>
    <visual>
      <origin rpy="1.5745317514920234 0.003601150001683928 1.6650413701206925" xyz="0.011992289866897352 -0.0007726988011287212 -5.201111709052532e-06"/>
      <geometry>
        <mesh filename="package://kortex_description/grippers/delto_3f/meshes/link_04.stl"/>
      </geometry>
      <material name="black"/>
    </visual>
    <collision>
      <origin rpy="1.5745317514920234 0.003601150001683928 1.6650413701206925" xyz="0.011992289866897352 -0.0007726988011287212 -5.201111709052532e-06"/>
      <geometry>
        <mesh filename="package://kortex_description/grippers/delto_3f/meshes/link_04.stl"/>
      </geometry>
    </collision>
  </link>
  <link name="right_F3_TIP">
    <inertial>
      <origin rpy="1.5708008179564292 -3.695361794919805e-05 1.5210948927815267" xyz="0.045 -0.000436 -7.22e-08"/>
      <mass value="0.013"/>
      <inertia ixx="1.5965708653714455e-06" ixy="0" ixz="0" iyy="1.2999999996018677e-06" iyz="0" izz="9.60129135026688e-07"/>
    </inertial>
    <visual>
      <origin rpy="1.5708745579876908 -1.019986385419891e-05 1.5204133624130758" xyz="0.044959448417087294 -0.0004226309811080281 2.3018946871860735e-07"/>
      <geometry>
        <mesh filename="package://kortex_description/grippers/delto_3f/meshes/link_tip_high.stl"/>
      </geometry>
      <material name="white"/>
    </visual>
    <collision>
      <origin rpy="1.5708745579876908 -1.019986385419891e-05 1.5204133624130758" xyz="0.044959448417087294 -0.0004226309811080281 2.3018946871860735e-07"/>
      <geometry>
        <mesh filename="package://kortex_description/grippers/delto_3f/meshes/link_tip_high.stl"/>
      </geometry>
    </collision>
  </link>
</robot>

